<?xml version="1.0" ?>
<!-- =================================================================================== -->
<!-- |    This document was autogenerated by xacro from urdf/genie.robot.xacro         | -->
<!-- |    EDITING THIS FILE BY HAND IS NOT RECOMMENDED                                 | -->
<!-- =================================================================================== -->
<robot name="genie"  xmlns:xacro="http://www.ros.org/wiki/xacro">
    <!-- Index -->
    <!-- body: [G1, G2] -->
    <!-- gripper: [dummy_hand, omnipicker, 120s, roh, skillhands6] -->
    <!-- <xacro:arg name="robot_model" default="G1" />
    <xacro:arg name="robot_model" default="G1" /> -->
    <!-- robot -->
    <!-- Material Definition -->

    <!-- <material name="black">
        <color rgba="0.0 0.0 0.0 1.0"/>
    </material>
    <material name="blue">
        <color rgba="0.0 0.0 0.8 1.0"/>
    </material>
    <material name="green">
        <color rgba="0.0 1.0 0.0 1.0"/>
    </material>
    <material name="grey">
        <color rgba="0.2 0.2 0.2 1.0"/>
    </material>
    <material name="orange">
        <color rgba="1.0 0.4235294117647059 0.0392156862745098 1.0"/>
    </material>
    <material name="brown">
        <color rgba="0.8705882352941177 0.8117647058823529 0.7647058823529411 1.0"/>
    </material>
    <material name="red">
        <color rgba="0.8 0.0 0.0 1.0"/>
    </material>
    <material name="white">
        <color rgba="1.0 1.0 1.0 1.0"/>
    </material>
    <material name="transparent">
        <color rgba="1.0 1.0 1.0 0.999"/>
    </material>
    <material name="default">
        <color rgba="0.752941176470588 0.752941176470588 0.752941176470588 1"/>
    </material> -->

    <xacro:property name="pkg_name" value="g1_robot_description"/>    <!-- 包名参数 -->

    <!-- links -->
    <link name="base_link">
        <inertial>
            <origin rpy="0.0 0.0 0.0" xyz="-0.0134486971267798 0.00152103941353612 -0.0320076754329413"/>
            <mass value="23.2085382238952"/>
            <inertia ixx="0.386955641760608" ixy="0.000135417314593726" ixz="0.00669301645720665" iyy="0.366800407621218" iyz="0.000105713634260505" izz="0.546852919828475"/>
        </inertial>
        <visual>
            <geometry>
                <mesh filename="package://${pkg_name}/urdf/g1/meshes/base_link.fbx"/>
            </geometry>
            <origin rpy="0.0 0.0 0.0" xyz="0.0 0.0 0.0"/>
            <material name="white">
                <color rgba="0.0 0.0 0.8 1.0"/>
            </material>
        </visual>
        <collision>
            <geometry>
                <mesh filename="package://${pkg_name}/urdf/g1/meshes/base_link.fbx"/>
            </geometry>
            <origin rpy="0.0 0.0 0.0" xyz="0.0 0.0 0.0"/>
        </collision>
    </link>
    <link name="body_link1">
        <inertial>
        <origin rpy="0.0 0.0 0.0" xyz="0.0338351537064605 -0.00248044044451858 0.000838431095422365"/>
        <mass value="3.26275452360108"/>
        <inertia ixx="0.0128301877197417" ixy="8.24967996575627e-06" ixz="1.38254543337324e-05" iyy="0.006104110250297" iyz="-7.99392548994692e-06" izz="0.0111721084996867"/>
        </inertial>
        <visual>
            <geometry>
                <mesh filename="package://${pkg_name}/urdf/g1/meshes/body_link1.fbx"/>
            </geometry>
            <origin rpy="0.0 0.0 0.0" xyz="0.0 0.0 0.0"/>
            <material name="blue"/>
        </visual>
        <collision>
            <geometry>
                <mesh filename="package://${pkg_name}/urdf/g1/meshes/body_link1.fbx"/>
            </geometry>
            <origin rpy="0.0 0.0 0.0" xyz="0.0 0.0 0.0"/>
        </collision>
    </link>
    <link name="body_link2">
        <inertial>
        <origin rpy="0.0 0.0 0.0" xyz="0.193733558855111 -0.000484180179482319 -0.00124011422952511"/>
        <mass value="7.53199207979272"/>
        <inertia ixx="0.016546682835947" ixy="0.000274441382484697" ixz="0.00102757387076422" iyy="0.0445441227006132" iyz="-0.000236858278708531" izz="0.0402036337794082"/>
        </inertial>
        <visual>
            <geometry>
                <mesh filename="package://${pkg_name}/urdf/g1/meshes/body_link2.fbx"/>
            </geometry>
            <origin rpy="0.0 0.0 -1.5707963267948966" xyz="0.0 0.0 0.0"/>
            <material name="white"/>
        </visual>
        <collision>
            <geometry>
                <mesh filename="package://${pkg_name}/urdf/g1/meshes/body_link2.fbx"/>
            </geometry>
            <origin rpy="0.0 0.0 -1.5707963267948966" xyz="0.0 0.0 0.0"/>
        </collision>
    </link>
   <link name="head_link1">
        <inertial>
        <origin rpy="0.0 0.0 0.0" xyz="0.0446068140025754 0.00241753143645124 0.0528373754603559"/>
        <mass value="0.414342871921048"/>
        <inertia ixx="0.000158695728344024" ixy="-1.04590928109554e-06" ixz="-6.58530903139189e-06" iyy="0.000117742864399469" iyz="-2.65011299996072e-06" izz="0.000170947040827065"/>
        </inertial>
        <visual>
            <geometry>
                <mesh filename="package://${pkg_name}/urdf/g1/meshes/head_link1.fbx"/>
            </geometry>
            <origin rpy="0.0 0.0 0.0" xyz="0.0 0.0 0.0"/>
        </visual>
        <collision>
            <geometry>
                <mesh filename="package://${pkg_name}/urdf/g1/meshes/head_link1.fbx"/>
            </geometry>
            <origin rpy="0.0 0.0 0.0" xyz="0.0 0.0 0.0"/>
        </collision>
    </link>
    <link name="head_link2">
        <inertial>
        <origin rpy="0.0 0.0 0.0" xyz="0.0257009265816389 0.0316254080188787 -3.77390122592164e-05"/>
        <mass value="0.707063977171202"/>
        <inertia ixx="0.00205409595373573" ixy="0.000347730118005016" ixz="-2.13857752451204e-06" iyy="0.00200357281313449" iyz="5.16150600423908e-08" izz="0.00184999028444405"/>
        </inertial>
        <visual>
            <geometry>
                <mesh filename="package://${pkg_name}/urdf/g1/meshes/head_link2.fbx"/>
            </geometry>
            <origin rpy="-3.141592653589793 0.0 0.0" xyz="0.0 0.0 0.0"/>
        </visual>
        <collision>
            <geometry>
                <mesh filename="package://${pkg_name}/urdf/g1/meshes/head_link2.fbx"/>
            </geometry>
            <origin rpy="-3.141592653589793 0.0 0.0" xyz="0.0 0.0 0.0"/>
        </collision>
    </link>

    <link name="arm_base_link"/>
    <link name="arm_l_base_link">
        <inertial>
        <origin rpy="0.0 0.0 0.0" xyz="-0.00020641 0.00057488 0.032296"/>
        <mass value="0.37595"/>
        <inertia ixx="0.00024335" ixy="1.2188e-06" ixz="-2.4281e-06" iyy="0.00024039" iyz="6.6932e-06" izz="0.00032195"/>
        </inertial>
        <visual>
            <geometry>
                <mesh filename="package://${pkg_name}/urdf/g1/meshes/arm_l_base_link.fbx"/>
            </geometry>
            <origin rpy="0.0 0.0 0.0" xyz="0.0 0.0 0.0"/>
        </visual>
        <collision>
            <geometry>
                <mesh filename="package://${pkg_name}/urdf/g1/meshes/arm_l_base_link.fbx"/>
            </geometry>
            <origin rpy="0.0 0.0 0.0" xyz="0.0 0.0 0.0"/>
        </collision>
    </link>
    <link name="arm_r_base_link">
        <inertial>
        <origin rpy="0.0 0.0 0.0" xyz="0.00020641 -0.00057488 0.034396"/>
        <mass value="0.37595"/>
        <inertia ixx="0.00024335" ixy="1.2188e-06" ixz="2.4281e-06" iyy="0.00024039" iyz="-6.6932e-06" izz="0.00032195"/>
        </inertial>
        <visual>
            <geometry>
                <mesh filename="package://${pkg_name}/urdf/g1/meshes/arm_r_base_link.fbx"/>
            </geometry>
            <origin rpy="0.0 0.0 0.0" xyz="0.0 0.0 0.0"/>
        </visual>
        <collision>
            <geometry>
                <mesh filename="package://${pkg_name}/urdf/g1/meshes/arm_r_base_link.fbx"/>
            </geometry>
            <origin rpy="0.0 0.0 0.0" xyz="0.0 0.0 0.0"/>
        </collision>
    </link>


    <!-- 3. 定义机器人根节点（可选，方便RVIZ定位） -->
    <link name="world"/>
    <joint name="world_to_base" type="fixed">
        <parent link="world"/>
        <child link="base_link"/>
        <origin xyz="0 0 0" rpy="0 0 0"/>
    </joint>

    <!-- joints waist -->
    <joint name="idx01_body_joint1" type="prismatic">
        <parent link="base_link"/>
        <child link="body_link1"/>
        <origin rpy="0.0 0.0 0.0" xyz="0.0 0.0 0.6485"/>
        <axis xyz="0.0 0.0 1.0"/>
        <limit effort="100.0" lower="0.0" upper="0.55" velocity="0.1"/>
    </joint>
    <joint name="idx02_body_joint2" type="revolute">
        <parent link="body_link1"/>
        <child link="body_link2"/>
        <!-- <origin rpy="-1.5707963267948966 0.0 0.0" xyz="0.131 0.0 0.0"/> -->
        <origin rpy="-1.5707963267948966 1.5707963267948966 0.0" xyz="0.131 0.0 0.0"/>
        <axis xyz="0.0 0.0 1.0"/>
        <limit effort="100.0" lower="0.0" upper="1.5707963267948966" velocity="0.5"/>
    </joint>

    <!-- joints head -->
    <joint name="idx11_head_joint1" type="revolute">
        <parent link="body_link2"/>
        <child link="head_link1"/>
        <!-- <origin rpy="1.5707963267948966 0.0 0.0" xyz="0.0 -0.441 0.0"/> -->
        <origin rpy="1.5707963267948966 0.0 -1.5707963267948966" xyz="-0.441 0.0  0.0"/>
        <axis xyz="0.0 0.0 1.0"/>
        <limit effort="50.0" lower="-1.5707963267948966" upper="1.5707963267948966" velocity="1.0"/>
    </joint>
    <joint name="idx12_head_joint2" type="revolute">
        <parent link="head_link1"/>
        <child link="head_link2"/>
        <!-- <origin rpy="-1.5707963267948966 0.0 0.0" xyz="0.050238 0.0 0.060065"/> -->
        <origin rpy="1.5707963267948966 0.0 0.0" xyz="0.050238 0.0 0.060065"/>
        <axis xyz="0.0 0.0 1.0"/>
        <limit effort="50.0" lower="-0.3490658503988659" upper="0.5235987755982988" velocity="1.0"/>
    </joint>

    <!-- joints arm base -->
    <joint name="idx10_arm_base_joint" type="fixed">
        <parent link="body_link2"/>
        <child link="arm_base_link"/>
        <!-- <origin rpy="1.5707963267948966 0.0 0.0" xyz="0.0 -0.305 0.0"/> -->
        <origin rpy="1.5707963267948966 0.0 0.0" xyz="-0.305 0.0 0.0"/>
        <axis xyz="0.0 0.0 1.0"/>
    </joint>
    <joint name="idx11_arm_l_base_joint" type="fixed">
        <parent link="arm_base_link"/>
        <child link="arm_l_base_link"/>
        <origin rpy="-1.5707963267948966 0.0 0.0" xyz="0.0 0.025 0.0"/>
        <axis xyz="1.0 0.0 0.0"/>
    </joint>
    <joint name="idx12_arm_r_base_joint" type="fixed">
        <parent link="arm_base_link"/>
        <child link="arm_r_base_link"/>
        <origin rpy="-1.5707963267948966 0.0 3.141592653589793" xyz="0.0 -0.025 0.0"/>
        <axis xyz="1.0 0.0 0.0"/>
    </joint>


    <xacro:include filename="./left_arm.xacro"/>
    <xacro:include filename="./right_arm.xacro"/>
    <xacro:include filename="./left_omnipicker.xacro"/>
    <xacro:create_left_omnipicker parent_link="arm_l_end_link" />

    <xacro:include filename="./right_omnipicker.xacro"/>
    <xacro:create_right_omnipicker parent_link="arm_r_end_link" />

</robot>