<?xml version="1.0"?>
<robot xmlns:xacro="http://www.ros.org/wiki/xacro">

    <link name="arm_l_link1">
        <inertial>
        <origin rpy="0 0 0" xyz="-0.0012655 -0.00043778 -0.018388"/>
        <mass value="0.4936"/>
        <inertia ixx="0.00075396" ixy="6.6935e-06" ixz="6.1141e-06" iyy="0.00065755" iyz="1.2196e-06" izz="0.00031848"/>
        </inertial>
        <visual>
            <origin rpy="0 0 0" xyz="0 0 0"/>
            <geometry>
                <mesh filename="package://${pkg_name}/urdf/g1/meshes/arm_l_link1.fbx"/>
            </geometry>
            <material name="white"/>
        </visual>
        <collision>
            <origin rpy="0 0 0" xyz="0 0 0"/>
            <geometry>
                <mesh filename="package://${pkg_name}/urdf/g1/meshes/arm_l_link1.fbx"/>
            </geometry>
            <material name="white"/>
        </collision>
        <!-- <collision>
            <geometry>
                <cylinder length="0.16642063483595848" radius="0.05579268228774888"/>
            </geometry>
            <origin rpy="0.0 0.0 -1.2566370614359172" xyz="0.0026814433577366636 0.0006133775157398935 -0.04071124829351902"/>
        </collision> -->
    </link>
    <link name="arm_l_link2">
        <inertial>
        <origin rpy="0 0 0" xyz="5.3037e-05 -0.078258 0.0047084"/>
        <mass value="0.46245"/>
        <inertia ixx="0.00065719" ixy="3.7112e-07" ixz="-3.6668e-06" iyy="0.00043459" iyz="-2.517e-05" izz="0.00072571"/>
        </inertial>
        <visual>
            <origin rpy="0 0 0" xyz="0 0 0"/>
            <geometry>
                <mesh filename="package://${pkg_name}/urdf/g1/meshes/arm_l_link2.fbx"/>
            </geometry>
            <material name="white"/>
        </visual>
        <collision>
            <origin rpy="0 0 0" xyz="0 0 0"/>
            <geometry>
                <mesh filename="package://${pkg_name}/urdf/g1/meshes/arm_l_link2.fbx"/>
            </geometry>
            <material name="white"/>
        </collision>
        <!-- <collision>
            <origin rpy="1.5707963267948966 0 0" xyz="0.0 -0.044062052 0.0009765625"/>
            <geometry>
                <cylinder length="0.18085919" radius="0.06302423"/>
            </geometry>
        </collision> -->
    </link>

    <link name="arm_l_link3">
        <inertial>
        <origin rpy="0 0 0" xyz="-0.0012032 0.0008714 -0.055265"/>
        <mass value="0.50026"/>
        <inertia ixx="0.0013016" ixy="3.1401e-06" ixz="1.4255e-05" iyy="0.001427" iyz="2.4361e-05" izz="0.00033587"/>
        </inertial>
        <visual>
            <origin rpy="0 0 0" xyz="0 0 0"/>
            <geometry>
                <mesh filename="package://${pkg_name}/urdf/g1/meshes/arm_l_link3.fbx"/>
            </geometry>
            <material name="white"/>
        </visual>
        <collision>
            <origin rpy="0 0 0" xyz="0 0 0"/>
            <geometry>
                <mesh filename="package://${pkg_name}/urdf/g1/meshes/arm_l_link3.fbx"/>
            </geometry>
            <material name="white"/>
        </collision>
        <!-- <collision>
            <origin rpy="3.141592653589793 -1.2246467991473532e-16 2.5132741228718345" xyz="-0.002745052027917949 0.000636008250640886 -0.07223940640687943"/>
            <geometry>
                <cylinder length="0.22069887816905975" radius="0.05423258091998755"/>
            </geometry>
        </collision> -->
    </link>

    <link name="arm_l_link4">
        <inertial>
        <origin rpy="0 0 0" xyz="3.7035e-05 -0.06248 0.0025377"/>
        <mass value="0.27473"/>
        <inertia ixx="0.00029284" ixy="4.6615e-07" ixz="6.2359e-08" iyy="0.00018853" iyz="-1.1062e-06" izz="0.00031238"/>
        </inertial>
        <visual>
            <origin rpy="0 0 0" xyz="0 0 0"/>
            <geometry>
                <mesh filename="package://${pkg_name}/urdf/g1/meshes/arm_l_link4.fbx"/>
            </geometry>
            <material name="white"/>
        </visual>
        <collision>
            <origin rpy="0 0 0" xyz="0 0 0"/>
            <geometry>
                <mesh filename="package://${pkg_name}/urdf/g1/meshes/arm_l_link4.fbx"/>
            </geometry>
            <material name="white"/>
        </collision>
        <!-- <collision>
            <origin rpy="1.5707963267948966 0 0" xyz="0.0 -0.03817895 -0.0043945312"/>
            <geometry>
                <cylinder length="0.154955404" radius="0.057891708"/>
            </geometry>
        </collision> -->
    </link>

    <link name="arm_l_link5">
        <inertial>
        <origin rpy="0 0 0" xyz="-7.9404e-07 -0.00023094 -0.024143"/>
        <mass value="0.25139"/>
        <inertia ixx="0.00023516" ixy="-1.3496e-09" ixz="-2.0314e-08" iyy="0.00028808" iyz="-1.2106e-05" izz="0.00013069"/>
        </inertial>
        <visual>
            <origin rpy="0 0 0" xyz="0 0 0"/>
            <geometry>
                <mesh filename="package://${pkg_name}/urdf/g1/meshes/arm_l_link5.fbx"/>
            </geometry>
            <material name="white"/>
        </visual>
        <collision>
            <origin rpy="0 0 0" xyz="0 0 0"/>
            <geometry>
                <mesh filename="package://${pkg_name}/urdf/g1/meshes/arm_l_link5.fbx"/>
            </geometry>
            <material name="white"/>
        </collision>
        <!-- <collision>
            <origin rpy="0.0 0.0 -0.6283185307179586" xyz="0.00013161953185003987 -5.835551655943335e-05 -0.033305803313851357"/>
            <geometry>
                <cylinder length="0.13452399894595146" radius="0.045614576801007695"/>
            </geometry>
        </collision> -->
    </link>

    <link name="arm_l_link6">
        <inertial>
        <origin rpy="0 0 0" xyz="1.769e-06 -0.086692 0.0025571"/>
        <mass value="0.26634"/>
        <inertia ixx="0.00031434" ixy="-2.9254e-09" ixz="1.0017e-07" iyy="0.00014464" iyz="-2.0329e-05" izz="0.0003245"/>
        </inertial>
        <visual>
            <origin rpy="0 0 0" xyz="0 0 0"/>
            <geometry>
                <mesh filename="package://${pkg_name}/urdf/g1/meshes/arm_l_link6.fbx"/>
            </geometry>
            <material name="white"/>
        </visual>
        <collision>
            <origin rpy="0 0 0" xyz="0 0 0"/>
            <geometry>
                <mesh filename="package://${pkg_name}/urdf/g1/meshes/arm_l_link6.fbx"/>
            </geometry>
            <material name="white"/>
        </collision>
        <!-- <collision>
            <origin rpy="-5.990089690983079e-19 -1.4805425285141327 -1.5677635369963552" xyz="0.0002549462426528953 -0.055477687883556816 -0.0019394332157672595"/>
            <geometry>
                <cylinder length="0.1816599826988493" radius="0.048507387167967514"/>
            </geometry>
        </collision> -->
    </link>

    <link name="arm_l_end_link">
        <inertial>
        <origin rpy="0 0 0" xyz="-7.5113e-05 -0.00024521 -0.016705"/>
        <mass value="0.06158"/>
        <inertia ixx="1.8407e-05" ixy="3.4796e-08" ixz="-3.2424e-09" iyy="1.818e-05" iyz="1.1327e-07" izz="2.8547e-05"/>
        </inertial>
        <visual>
            <origin rpy="0 0 0" xyz="0 0 0"/>
            <geometry>
                <mesh filename="package://${pkg_name}/urdf/g1/meshes/arm_l_end_link.fbx"/>
            </geometry>
            <material name="white"/>
        </visual>
        <collision>
            <origin rpy="0 0 0" xyz="0 0 0"/>
            <geometry>
                <mesh filename="package://${pkg_name}/urdf/g1/meshes/arm_l_end_link.fbx"/>
            </geometry>
            <material name="white"/>
        </collision>
        <!-- <collision>
            <origin rpy="3.141592653589793 -1.2246467991473532e-16 3.141592653589793" xyz="-4.552953707661759e-05 -0.002300474691790042 -0.02249999972991645"/>
            <geometry>
                <cylinder length="0.045999998692423105" radius="0.030799950382754494"/>
            </geometry>
        </collision> -->
    </link>

    <!-- Joints -->
    <joint name="idx21_arm_l_joint1" type="revolute">
        <parent link="arm_l_base_link"/>
        <child link="arm_l_link1"/>
        <origin rpy="0 0 0" xyz="0.0 0.0 0.1859"/>
        <axis xyz="0.0 0.0 1.0"/>
        <limit effort="60.0" lower="-3.14" upper="3.14" velocity="3.14"/>
    </joint>

    <joint name="idx22_arm_l_joint2" type="revolute">
        <parent link="arm_l_link1"/>
        <child link="arm_l_link2"/>
        <origin rpy="-1.5707963267948966 0.0 1.5707963267948966" xyz="0.0 0.0 0.0"/>
        <axis xyz="0.0 0.0 1.0"/>
        <limit effort="60.0" lower="-2.09" upper="1.48" velocity="3.14"/>
    </joint>
    
    <joint name="idx23_arm_l_joint3" type="revolute">
        <parent link="arm_l_link2"/>
        <child link="arm_l_link3"/>
        <origin rpy="-1.5707963267948966 1.5707963267948966 3.141592653589793" xyz="0.0 -0.305 0.0"/>
        <axis xyz="0.0 0.0 1.0"/>
        <limit effort="60.0" lower="-3.10" upper="3.10" velocity="3.14"/>
    </joint>

    <joint name="idx24_arm_l_joint4" type="revolute">
        <parent link="arm_l_link3"/>
        <child link="arm_l_link4"/>
        <origin rpy="-1.5707963267948966 0.0 3.141592653589793" xyz="0.0 0.0 0.0"/>
        <axis xyz="0.0 0.0 1.0"/>
        <limit effort="60.0" lower="-1.48" upper="1.48" velocity="3.14"/>
    </joint>
    <joint name="idx25_arm_l_joint5" type="revolute">
        <parent link="arm_l_link4"/>
        <child link="arm_l_link5"/>
        <origin rpy="-1.5707963267948966 0.0 -3.141592653589793" xyz="0.0 -0.1975 0.0"/>
        <axis xyz="0.0 0.0 1.0"/>
        <limit effort="30.0" lower="-3.10" upper="3.10" velocity="3.14"/>
    </joint>
    <joint name="idx26_arm_l_joint6" type="revolute">
        <parent link="arm_l_link5"/>
        <child link="arm_l_link6"/>
        <origin rpy="-1.5707963267948966 0.0 0.0" xyz="0.0 0.0 0.0"/>
        <axis xyz="0.0 0.0 1.0"/>
        <limit effort="30.0" lower="-1.74" upper="1.74" velocity="3.14"/>
    </joint>
    <joint name="idx27_arm_l_joint7" type="revolute">
        <origin rpy="1.5707963267948966 0.0 0.0" xyz="0.0 -0.1805 0.0"/>
        <parent link="arm_l_link6"/>
        <child link="arm_l_end_link"/>
        <axis xyz="0.0 0.0 1.0"/>
        <limit effort="30.0" lower="-3.10" upper="3.10" velocity="3.14"/>
    </joint>


</robot>