<?xml version="1.0"?>
<robot xmlns:xacro="http://www.ros.org/wiki/xacro">

    <!-- links -->
    <link name="arm_r_link1">
        <inertial>
        <origin rpy="0 0 0" xyz="0.0012679 -0.0001581 -0.018109"/>
        <mass value="0.4936"/>
        <inertia ixx="0.00075396" ixy="-2.4144e-06" ixz="-1.8364e-06" iyy="0.0006605" iyz="1.2174e-06" izz="0.00031553"/>
        </inertial>
        <visual>
            <origin rpy="0 0 0" xyz="0 0 0"/>
            <geometry>
                <mesh filename="package://${pkg_name}/urdf/g1/meshes/arm_r_link1.fbx"/>
            </geometry>
            <material name="white"/>
        </visual>
        <collision>
            <origin rpy="0 0 0" xyz="0 0 0"/>
            <geometry>
                <mesh filename="package://${pkg_name}/urdf/g1/meshes/arm_r_link1.fbx"/>
            </geometry>
        </collision>
        <!-- <collision>
            <origin rpy="-3.141592653589793 -1.2246467991473535e-16 1.2566370614359175" xyz="0.00018724019569230644 -0.002004870648449318 -0.04071185737848282"/>
            <geometry>
                <cylinder length="0.16642716526985168" radius="0.0548390473201415"/>
            </geometry>
        </collision> -->
    </link>

    <link name="arm_r_link2">
        <inertial>
        <origin rpy="0 0 0" xyz="-0.00044207 -0.082298 0.00019486"/>
        <mass value="0.41662"/>
        <inertia ixx="0.00054592" ixy="4.7265e-06" ixz="2.4946e-06" iyy="0.00039507" iyz="-2.0629e-05" izz="0.00057791"/>
        </inertial>
        <visual>
            <origin rpy="0 0 0" xyz="0 0 0"/>
            <geometry>
                <mesh filename="package://${pkg_name}/urdf/g1/meshes/arm_r_link2.fbx"/>
            </geometry>
            <material name="white"/>
        </visual>
        <collision>
            <origin rpy="0 0 0" xyz="0 0 0"/>
            <geometry>
                <mesh filename="package://${pkg_name}/urdf/g1/meshes/arm_r_link2.fbx"/>
            </geometry>
        </collision>
        <!-- <collision>
            <origin rpy="1.5707963267948966 0 0" xyz="0.0 -0.044062052 0.0009765625"/>
            <geometry>
                <cylinder length="0.18085919" radius="0.06302423"/>
            </geometry>
        </collision> -->
    </link>

    <link name="arm_r_link3">
        <inertial>
        <origin rpy="0 0 0" xyz="0.0010558 4.4416e-05 -0.056128"/>
        <mass value="0.49413"/>
        <inertia ixx="0.0013405" ixy="-6.8527e-07" ixz="-1.3381e-05" iyy="0.00142" iyz="2.8511e-05" izz="0.00037605"/>
        </inertial>
        <visual>
            <origin rpy="0 0 0" xyz="0 0 0"/>
            <geometry>
                <mesh filename="package://${pkg_name}/urdf/g1/meshes/arm_r_link3.fbx"/>
            </geometry>
            <material name="white"/>
        </visual>
        <collision>
            <origin rpy="0 0 0" xyz="0 0 0"/>
            <geometry>
                <mesh filename="package://${pkg_name}/urdf/g1/meshes/arm_r_link3.fbx"/>
            </geometry>
        </collision>
        <!-- <collision>
            <origin rpy="0 0 0" xyz="0.0006559932284637068 -2.2628975236450855e-05 -0.07219303026795387"/>
            <geometry>
                <cylinder length="0.22061403840780258" radius="0.05216156143823925"/>
            </geometry>
        </collision> -->
    </link>

    <link name="arm_r_link4">
        <inertial>
        <origin rpy="0 0 0" xyz="2.4212e-05 -0.06248 0.002536"/>
        <mass value="0.27473"/>
        <inertia ixx="0.00029283" ixy="4.5586e-07" ixz="5.8042e-08" iyy="0.00018852" iyz="-1.116e-06" izz="0.00031238"/>
        </inertial>
        <visual>
            <origin rpy="0 0 0" xyz="0 0 0"/>
            <geometry>
                <mesh filename="package://${pkg_name}/urdf/g1/meshes/arm_r_link4.fbx"/>
            </geometry>
            <material name="white"/>
        </visual>
        <collision>
            <origin rpy="0 0 0" xyz="0 0 0"/>
            <geometry>
                <mesh filename="package://${pkg_name}/urdf/g1/meshes/arm_r_link4.fbx"/>
            </geometry>
        </collision>
        <!-- <collision>
            <origin rpy="1.5707963267948966 0 0" xyz="0.0 -0.03817895 -0.0043945312"/>
            <geometry>
                <cylinder length="0.154955404" radius="0.057891708"/>
            </geometry>
        </collision> -->
    </link>

    <link name="arm_r_link5">
        <inertial>
        <origin rpy="0 0 0" xyz="2.6223e-06 -0.00023041 -0.024141"/>
        <mass value="0.25139"/>
        <inertia ixx="0.00023516" ixy="-6.5868e-09" ixz="-1.9428e-08" iyy="0.00028807" iyz="-1.2108e-05" izz="0.00013068"/>
        </inertial>
        <visual>
            <origin rpy="0 0 0" xyz="0 0 0"/>
            <geometry>
                <mesh filename="package://${pkg_name}/urdf/g1/meshes/arm_r_link5.fbx"/>
            </geometry>
            <material name="white"/>
        </visual>
        <collision>
            <origin rpy="0 0 0" xyz="0 0 0"/>
            <geometry>
                <mesh filename="package://${pkg_name}/urdf/g1/meshes/arm_r_link5.fbx"/>
            </geometry>
        </collision>
        <!-- <collision>
            <origin rpy="0 0 0" xyz="-0.00022255510134868567 -4.227476414728204e-05 -0.03344946540892124"/>
            <geometry>
                <cylinder length="0.13423806056380272" radius="0.04562028545392604"/>
            </geometry>
        </collision> -->
    </link>
    <link name="arm_r_link6">
        <inertial>
        <origin rpy="0 0 0" xyz="5.0382e-06 -0.086696 0.002556"/>
        <mass value="0.26634"/>
        <inertia ixx="0.00031434" ixy="-1.2113e-09" ixz="1.0011e-07" iyy="0.00014464" iyz="-2.033e-05" izz="0.00032449"/>
        </inertial>
        <visual>
            <origin rpy="0 0 0" xyz="0 0 0"/>
            <geometry>
                <mesh filename="package://${pkg_name}/urdf/g1/meshes/arm_r_link6.fbx"/>
            </geometry>
            <material name="white"/>
        </visual>
        <collision>
            <origin rpy="0 0 0" xyz="0 0 0"/>
            <geometry>
                <mesh filename="package://${pkg_name}/urdf/g1/meshes/arm_r_link6.fbx"/>
            </geometry>
        </collision>
        <!-- <collision>
            <origin rpy="0.0 -1.4835107730827122 -1.56897465223053" xyz="-1.7782549414354032e-05 -0.05507596972928094 -0.0017447156928267265"/>
            <geometry>
                <cylinder length="0.18272488500982115" radius="0.04857149291994264"/>
            </geometry>
        </collision> -->
    </link>

    <link name="arm_r_end_link">
        <inertial>
        <origin rpy="0 0 0" xyz="-7.5134e-05 -0.00024521 -0.016705"/>
        <mass value="0.06158"/>
        <inertia ixx="1.8407e-05" ixy="3.4818e-08" ixz="-3.2902e-09" iyy="1.818e-05" iyz="1.1326e-07" izz="2.8547e-05"/>
        </inertial>
        <visual>
            <origin rpy="0 0 0" xyz="0 0 0"/>
            <geometry>
                <mesh filename="package://${pkg_name}/urdf/g1/meshes/arm_r_end_link.fbx"/>
            </geometry>
            <material name="white"/>
        </visual>
        <collision>
            <origin rpy="0 0 0" xyz="0 0 0"/>
            <geometry>
                <mesh filename="package://${pkg_name}/urdf/g1/meshes/arm_r_end_link.fbx"/>
            </geometry>
        </collision>
        <!-- <collision>
            <origin rpy="3.141592653589793 -1.2246467991473532e-16 3.141592653589793" xyz="-4.552953707661759e-05 -0.002300474691790042 -0.02249999972991645"/>
            <geometry>
                <cylinder length="0.045999998692423105" radius="0.030799950382754494"/>
            </geometry>
        </collision> -->
    </link>

    <!-- joints -->
    <joint name="idx61_arm_r_joint1" type="revolute">
        <parent link="arm_r_base_link"/>
        <child link="arm_r_link1"/>
        <origin rpy="0 0 0" xyz="0.0 0.0 0.188"/>
        <axis xyz="0.0 0.0 1.0"/>
        <limit effort="60.0" lower="-3.14" upper="3.14" velocity="3.14"/>
    </joint>
    <joint name="idx62_arm_r_joint2" type="revolute">
        <parent link="arm_r_link1"/>
        <child link="arm_r_link2"/>
        <origin rpy="-1.5707963267948966 0.0 -1.5707963267948966" xyz="0.0 0.0 0.0"/>
        <axis xyz="0.0 0.0 1.0"/>
        <limit effort="60.0" lower="-1.48" upper="2.09" velocity="3.14"/>
    </joint>
    <joint name="idx63_arm_r_joint3" type="revolute">
        <parent link="arm_r_link2"/>
        <child link="arm_r_link3"/>
        <origin rpy="-1.5707963267948966 -1.5707963267948966 3.141592653589793" xyz="0.0 -0.305 0.0"/>
        <axis xyz="0.0 0.0 1.0"/>
        <limit effort="60.0" lower="-3.10" upper="3.10" velocity="3.14"/>
    </joint>
    <joint name="idx64_arm_r_joint4" type="revolute">
        <parent link="arm_r_link3"/>
        <child link="arm_r_link4"/>
        <origin rpy="-1.5707963267948966 0.0 3.141592653589793" xyz="0.0 0.0 0.0"/>
        <axis xyz="0.0 0.0 1.0"/>
        <limit effort="60.0" lower="-1.48" upper="1.48" velocity="3.14"/>
    </joint>
    <joint name="idx65_arm_r_joint5" type="revolute">
        <parent link="arm_r_link4"/>
        <child link="arm_r_link5"/>
        <origin rpy="-1.5707963267948966 0.0 -3.141592653589793" xyz="0.0 -0.1975 0.0"/>
        <axis xyz="0.0 0.0 1.0"/>
        <limit effort="30.0" lower="-3.10" upper="3.10" velocity="3.14"/>
    </joint>
    <joint name="idx66_arm_r_joint6" type="revolute">
        <parent link="arm_r_link5"/>
        <child link="arm_r_link6"/>
        <origin rpy="-1.5707963267948966 0.0 0.0" xyz="0.0 0.0 0.0"/>
        <axis xyz="0.0 0.0 1.0"/>
        <limit effort="30.0" lower="-1.74" upper="1.74" velocity="3.14"/>
    </joint>
    <joint name="idx67_arm_r_joint7" type="revolute">
        <origin rpy="1.5707963267948966 0.0 0.0" xyz="0.0 -0.1805 0.0"/>
        <parent link="arm_r_link6"/>
        <child link="arm_r_end_link"/>
        <axis xyz="0.0 0.0 1.0"/>
        <limit effort="30.0" lower="-3.10" upper="3.10" velocity="3.14"/>
    </joint>


</robot>